[2020-02-17 11:24:58 -0500] [28774] [INFO] Goin' Fast @ http://0.0.0.0:8000
[2020-02-17 11:24:58 -0500] [28774] [INFO] Starting worker [28774]
[2020-02-17 11:25:20 -0500] - (sanic.access)[INFO][127.0.0.1:33128]: OPTIONS http://gaia.manizales.unal.edu.co:3200/aiplanner/auth/sign-up  200 2
[2020-02-17 11:25:20 -0500] - (sanic.access)[INFO][127.0.0.1:33130]: POST http://gaia.manizales.unal.edu.co:3200/aiplanner/auth/sign-up  404 47
[2020-02-17 11:26:24 -0500] [28825] [INFO] Goin' Fast @ http://0.0.0.0:8000
[2020-02-17 11:26:24 -0500] [28825] [ERROR] Unable to start server
Traceback (most recent call last):
  File "/home/froac/anaconda3/envs/aiplanner/lib/python3.7/site-packages/sanic/server.py", line 860, in serve
    http_server = loop.run_until_complete(server_coroutine)
  File "uvloop/loop.pyx", line 1417, in uvloop.loop.Loop.run_until_complete
  File "uvloop/loop.pyx", line 1686, in create_server
OSError: [Errno 98] error while attempting to bind on address ('0.0.0.0', 8000): address already in use
[2020-02-17 11:26:24 -0500] [28825] [INFO] Server Stopped
[2020-02-17 11:26:29 -0500] - (sanic.access)[INFO][127.0.0.1:33140]: OPTIONS http://gaia.manizales.unal.edu.co:3200/aiplanner/auth/sign-up  200 2
[2020-02-17 11:26:29 -0500] - (sanic.access)[INFO][127.0.0.1:33142]: POST http://gaia.manizales.unal.edu.co:3200/aiplanner/auth/sign-up  404 47
[2020-02-17 11:26:51 -0500] - (sanic.access)[INFO][127.0.0.1:33148]: OPTIONS http://gaia.manizales.unal.edu.co:3200/aiplanner/auth/sign-up  200 2
[2020-02-17 11:26:51 -0500] - (sanic.access)[INFO][127.0.0.1:33150]: POST http://gaia.manizales.unal.edu.co:3200/aiplanner/auth/sign-up  404 47
[2020-02-17 11:27:10 -0500] [28774] [ERROR] Exception occurred while handling uri: 'http://gaia.manizales.unal.edu.co:3200/aiplanner/'
Traceback (most recent call last):
  File "/home/froac/anaconda3/envs/aiplanner/lib/python3.7/site-packages/sanic/app.py", line 918, in handle_request
    handler, args, kwargs, uri = self.router.get(request)
  File "/home/froac/anaconda3/envs/aiplanner/lib/python3.7/site-packages/sanic/router.py", line 407, in get
    return self._get(request.path, request.method, "")
  File "/home/froac/anaconda3/envs/aiplanner/lib/python3.7/site-packages/sanic/router.py", line 470, in _get
    raise NotFound("Requested URL {} not found".format(url))
sanic.exceptions.NotFound: Requested URL /aiplanner/ not found
[2020-02-17 11:27:10 -0500] - (sanic.access)[INFO][127.0.0.1:33156]: GET http://gaia.manizales.unal.edu.co:3200/aiplanner/  404 42
[2020-02-17 11:27:13 -0500] [28774] [ERROR] Exception occurred while handling uri: 'http://gaia.manizales.unal.edu.co:3200/aiplanner/'
Traceback (most recent call last):
  File "/home/froac/anaconda3/envs/aiplanner/lib/python3.7/site-packages/sanic/app.py", line 918, in handle_request
    handler, args, kwargs, uri = self.router.get(request)
  File "/home/froac/anaconda3/envs/aiplanner/lib/python3.7/site-packages/sanic/router.py", line 407, in get
    return self._get(request.path, request.method, "")
  File "/home/froac/anaconda3/envs/aiplanner/lib/python3.7/site-packages/sanic/router.py", line 470, in _get
    raise NotFound("Requested URL {} not found".format(url))
sanic.exceptions.NotFound: Requested URL /aiplanner/ not found
[2020-02-17 11:27:13 -0500] - (sanic.access)[INFO][127.0.0.1:33158]: GET http://gaia.manizales.unal.edu.co:3200/aiplanner/  404 42
[2020-02-17 11:28:24 -0500] - (sanic.access)[INFO][127.0.0.1:33174]: OPTIONS http://gaia.manizales.unal.edu.co:3200/aiplanner/auth/sign-up  200 2
[2020-02-17 11:28:24 -0500] - (sanic.access)[INFO][127.0.0.1:33176]: POST http://gaia.manizales.unal.edu.co:3200/aiplanner/auth/sign-up  201 167
[2020-02-17 11:48:06 -0500] - (sanic.access)[INFO][127.0.0.1:33364]: OPTIONS http://gaia.manizales.unal.edu.co:3200/aiplanner/auth/sign-up  200 2
[2020-02-17 11:48:06 -0500] - (sanic.access)[INFO][127.0.0.1:33366]: POST http://gaia.manizales.unal.edu.co:3200/aiplanner/auth/sign-up  201 167
[2020-02-17 11:56:36 -0500] [28774] [ERROR] Exception occurred while handling uri: 'http://gaia.manizales.unal.edu.co:3200/aiplanner/'
Traceback (most recent call last):
  File "/home/froac/anaconda3/envs/aiplanner/lib/python3.7/site-packages/sanic/app.py", line 918, in handle_request
    handler, args, kwargs, uri = self.router.get(request)
  File "/home/froac/anaconda3/envs/aiplanner/lib/python3.7/site-packages/sanic/router.py", line 407, in get
    return self._get(request.path, request.method, "")
  File "/home/froac/anaconda3/envs/aiplanner/lib/python3.7/site-packages/sanic/router.py", line 470, in _get
    raise NotFound("Requested URL {} not found".format(url))
sanic.exceptions.NotFound: Requested URL /aiplanner/ not found
[2020-02-17 11:56:36 -0500] - (sanic.access)[INFO][127.0.0.1:33404]: GET http://gaia.manizales.unal.edu.co:3200/aiplanner/  404 42
[2020-02-17 11:56:42 -0500] [28774] [ERROR] Exception occurred while handling uri: 'http://gaia.manizales.unal.edu.co:3200/aiplanner/auth/'
Traceback (most recent call last):
  File "/home/froac/anaconda3/envs/aiplanner/lib/python3.7/site-packages/sanic/app.py", line 918, in handle_request
    handler, args, kwargs, uri = self.router.get(request)
  File "/home/froac/anaconda3/envs/aiplanner/lib/python3.7/site-packages/sanic/router.py", line 407, in get
    return self._get(request.path, request.method, "")
  File "/home/froac/anaconda3/envs/aiplanner/lib/python3.7/site-packages/sanic/router.py", line 470, in _get
    raise NotFound("Requested URL {} not found".format(url))
sanic.exceptions.NotFound: Requested URL /aiplanner/auth/ not found
[2020-02-17 11:56:42 -0500] - (sanic.access)[INFO][127.0.0.1:33406]: GET http://gaia.manizales.unal.edu.co:3200/aiplanner/auth/  404 47
[2020-02-17 11:56:45 -0500] [28774] [ERROR] Exception occurred while handling uri: 'http://gaia.manizales.unal.edu.co:3200/aiplanner/auth/sign-up'
Traceback (most recent call last):
  File "/home/froac/anaconda3/envs/aiplanner/lib/python3.7/site-packages/sanic/app.py", line 918, in handle_request
    handler, args, kwargs, uri = self.router.get(request)
  File "/home/froac/anaconda3/envs/aiplanner/lib/python3.7/site-packages/sanic/router.py", line 407, in get
    return self._get(request.path, request.method, "")
  File "/home/froac/anaconda3/envs/aiplanner/lib/python3.7/site-packages/sanic/router.py", line 447, in _get
    raise method_not_supported
sanic.exceptions.MethodNotSupported: Method GET not allowed for URL /aiplanner/auth/sign-up
[2020-02-17 11:56:45 -0500] - (sanic.access)[INFO][127.0.0.1:33410]: GET http://gaia.manizales.unal.edu.co:3200/aiplanner/auth/sign-up  405 61
[2020-02-17 13:23:12 -0500] [28774] [ERROR] Exception occurred while handling uri: 'http://gaia.manizales.unal.edu.co:3200/aiplanner/'
Traceback (most recent call last):
  File "/home/froac/anaconda3/envs/aiplanner/lib/python3.7/site-packages/sanic/app.py", line 918, in handle_request
    handler, args, kwargs, uri = self.router.get(request)
  File "/home/froac/anaconda3/envs/aiplanner/lib/python3.7/site-packages/sanic/router.py", line 407, in get
    return self._get(request.path, request.method, "")
  File "/home/froac/anaconda3/envs/aiplanner/lib/python3.7/site-packages/sanic/router.py", line 470, in _get
    raise NotFound("Requested URL {} not found".format(url))
sanic.exceptions.NotFound: Requested URL /aiplanner/ not found
[2020-02-17 13:23:12 -0500] - (sanic.access)[INFO][127.0.0.1:33970]: GET http://gaia.manizales.unal.edu.co:3200/aiplanner/  404 42
[2020-02-17 13:23:16 -0500] [28774] [ERROR] Exception occurred while handling uri: 'http://gaia.manizales.unal.edu.co:3200/aiplanner/auth'
Traceback (most recent call last):
  File "/home/froac/anaconda3/envs/aiplanner/lib/python3.7/site-packages/sanic/app.py", line 918, in handle_request
    handler, args, kwargs, uri = self.router.get(request)
  File "/home/froac/anaconda3/envs/aiplanner/lib/python3.7/site-packages/sanic/router.py", line 407, in get
    return self._get(request.path, request.method, "")
  File "/home/froac/anaconda3/envs/aiplanner/lib/python3.7/site-packages/sanic/router.py", line 470, in _get
    raise NotFound("Requested URL {} not found".format(url))
sanic.exceptions.NotFound: Requested URL /aiplanner/auth not found
[2020-02-17 13:23:16 -0500] - (sanic.access)[INFO][127.0.0.1:33972]: GET http://gaia.manizales.unal.edu.co:3200/aiplanner/auth  404 46
[2020-02-17 13:23:24 -0500] [28774] [ERROR] Exception occurred while handling uri: 'http://gaia.manizales.unal.edu.co:3200/aiplanner/auth/sign-up'
Traceback (most recent call last):
  File "/home/froac/anaconda3/envs/aiplanner/lib/python3.7/site-packages/sanic/app.py", line 918, in handle_request
    handler, args, kwargs, uri = self.router.get(request)
  File "/home/froac/anaconda3/envs/aiplanner/lib/python3.7/site-packages/sanic/router.py", line 407, in get
    return self._get(request.path, request.method, "")
  File "/home/froac/anaconda3/envs/aiplanner/lib/python3.7/site-packages/sanic/router.py", line 447, in _get
    raise method_not_supported
sanic.exceptions.MethodNotSupported: Method GET not allowed for URL /aiplanner/auth/sign-up
[2020-02-17 13:23:24 -0500] - (sanic.access)[INFO][127.0.0.1:33976]: GET http://gaia.manizales.unal.edu.co:3200/aiplanner/auth/sign-up  405 61
[2020-02-18 09:27:08 -0500] - (sanic.access)[INFO][127.0.0.1:45572]: OPTIONS http://gaia.manizales.unal.edu.co:3200/aiplanner/auth/login  200 2
[2020-02-18 09:27:08 -0500] - (sanic.access)[INFO][127.0.0.1:45576]: POST http://gaia.manizales.unal.edu.co:3200/aiplanner/auth/login  404 48
[2020-02-18 09:27:25 -0500] - (sanic.access)[INFO][127.0.0.1:45578]: OPTIONS http://gaia.manizales.unal.edu.co:3200/aiplanner/auth/sign-up  200 2
[2020-02-18 09:27:25 -0500] - (sanic.access)[INFO][127.0.0.1:45580]: POST http://gaia.manizales.unal.edu.co:3200/aiplanner/auth/sign-up  201 173
[2020-02-18 09:27:41 -0500] - (sanic.access)[INFO][127.0.0.1:45590]: OPTIONS http://gaia.manizales.unal.edu.co:3200/aiplanner/user/problems  200 2
[2020-02-18 09:27:41 -0500] - (sanic.access)[INFO][127.0.0.1:45592]: GET http://gaia.manizales.unal.edu.co:3200/aiplanner/user/problems  200 2322
[2020-02-18 09:27:46 -0500] - (sanic.access)[INFO][127.0.0.1:45594]: OPTIONS http://gaia.manizales.unal.edu.co:3200/aiplanner/user/problems  200 2
[2020-02-18 09:27:46 -0500] - (sanic.access)[INFO][127.0.0.1:45596]: GET http://gaia.manizales.unal.edu.co:3200/aiplanner/user/problems  200 2322
[2020-02-18 09:28:04 -0500] - (sanic.access)[INFO][127.0.0.1:45598]: OPTIONS http://gaia.manizales.unal.edu.co:3200/aiplanner/user/problems  200 2
[2020-02-18 09:28:04 -0500] - (sanic.access)[INFO][127.0.0.1:45600]: GET http://gaia.manizales.unal.edu.co:3200/aiplanner/user/problems  200 2322
[2020-02-18 09:28:12 -0500] - (sanic.access)[INFO][127.0.0.1:45604]: OPTIONS http://gaia.manizales.unal.edu.co:3200/aiplanner/user/strip/problem  200 2
[2020-02-18 09:28:12 -0500] - (sanic.access)[INFO][127.0.0.1:45606]: POST http://gaia.manizales.unal.edu.co:3200/aiplanner/user/strip/problem  200 137
[2020-02-18 09:29:58 -0500] - (sanic.access)[INFO][127.0.0.1:45640]: OPTIONS http://gaia.manizales.unal.edu.co:3200/aiplanner/user/strip/problem  200 2
[2020-02-18 09:29:58 -0500] - (sanic.access)[INFO][127.0.0.1:45642]: POST http://gaia.manizales.unal.edu.co:3200/aiplanner/user/strip/problem  200 137
[2020-02-18 09:30:09 -0500] - (sanic.access)[INFO][127.0.0.1:45646]: OPTIONS http://gaia.manizales.unal.edu.co:3200/aiplanner/user/problems  200 2
[2020-02-18 09:30:09 -0500] - (sanic.access)[INFO][127.0.0.1:45648]: GET http://gaia.manizales.unal.edu.co:3200/aiplanner/user/problems  200 2433
[2020-02-18 09:30:20 -0500] - (sanic.access)[INFO][127.0.0.1:45650]: OPTIONS http://gaia.manizales.unal.edu.co:3200/aiplanner/user/htn/problem  200 2
[2020-02-18 09:30:20 -0500] - (sanic.access)[INFO][127.0.0.1:45652]: POST http://gaia.manizales.unal.edu.co:3200/aiplanner/user/htn/problem  200 258
[2020-02-18 14:00:29 -0500] - (sanic.access)[INFO][127.0.0.1:48204]: OPTIONS http://gaia.manizales.unal.edu.co:3200/aiplanner/auth/login  200 2
[2020-02-18 14:00:29 -0500] - (sanic.access)[INFO][127.0.0.1:48206]: POST http://gaia.manizales.unal.edu.co:3200/aiplanner/auth/login  200 173
[2020-02-18 14:00:35 -0500] - (sanic.access)[INFO][127.0.0.1:48208]: OPTIONS http://gaia.manizales.unal.edu.co:3200/aiplanner/user/problems  200 2
[2020-02-18 14:00:35 -0500] - (sanic.access)[INFO][127.0.0.1:48210]: GET http://gaia.manizales.unal.edu.co:3200/aiplanner/user/problems  200 2665
